Workbook
Name \a: #REF!
Name \b: #REF!
Name \g: #REF!
Name \p: #REF!
Name __123Graph_A: '[2]#REF'!$E$11:$L$11
Name __123Graph_A: '[3]#REF'!$E$11:$L$11
Name __123Graph_B: '[2]#REF'!$E$12:$L$12
Name __123Graph_B: '[3]#REF'!$E$12:$L$12
Name __123Graph_C: '[2]#REF'!$E$10:$L$10
Name __123Graph_C: '[3]#REF'!$E$10:$L$10
Name __123Graph_X: '[2]#REF'!$E$8:$L$8
Name __123Graph_X: '[3]#REF'!$E$8:$L$8
Name _123: #REF!
Name _123: #REF!
Name _123: #REF!
Name _2IMPORT_RANGE: '[5]#REF'!$A$2:$K$34
Name _5IMPORT_RANGE: '[2]#REF'!$A$2:$K$34
Name _6IMPORT_RANGE: '[3]#REF'!$A$2:$K$34
Name _PS1: '[5]#REF'!$A$1:$X$45
Name _PS1: '[2]#REF'!$A$1:$X$45
Name _PS1: '[3]#REF'!$A$1:$X$45
Name _PS10: '[5]#REF'!$A$1:$Q$63
Name _PS10: '[2]#REF'!$A$1:$Q$63
Name _PS10: '[3]#REF'!$A$1:$Q$63
Name _PS11: '[5]#REF'!$A$1:$X$64
Name _PS11: '[2]#REF'!$A$1:$X$64
Name _PS11: '[3]#REF'!$A$1:$X$64
Name _PS12: '[5]#REF'!$A$1:$P$58
Name _PS12: '[2]#REF'!$A$1:$P$58
Name _PS12: '[3]#REF'!$A$1:$P$58
Name _PS13: '[5]#REF'!$A$1:$U$60
Name _PS13: '[2]#REF'!$A$1:$U$60
Name _PS13: '[3]#REF'!$A$1:$U$60
Name _PS14: '[5]#REF'!#REF!
Name _PS14: '[2]#REF'!#REF!
Name _PS14: '[3]#REF'!#REF!
Name _PS15: '[5]#REF'!$A$1:$Z$44
Name _PS15: '[2]#REF'!$A$1:$Z$44
Name _PS15: '[3]#REF'!$A$1:$Z$44
Name _PS16: '[5]#REF'!$A$1:$M$60
Name _PS16: '[2]#REF'!$A$1:$M$60
Name _PS16: '[3]#REF'!$A$1:$M$60
Name _PS17: '[5]#REF'!$B$1:$T$50
Name _PS17: '[2]#REF'!$B$1:$T$50
Name _PS17: '[3]#REF'!$B$1:$T$50
Name _PS18: '[5]#REF'!$A$1:$U$63
Name _PS18: '[2]#REF'!$A$1:$U$63
Name _PS18: '[3]#REF'!$A$1:$U$63
Name _PS19: '[5]#REF'!$A$1:$S$48
Name _PS19: '[2]#REF'!$A$1:$S$48
Name _PS19: '[3]#REF'!$A$1:$S$48
Name _PS2: '[5]#REF'!$A$1:$W$65
Name _PS2: '[2]#REF'!$A$1:$W$65
Name _PS2: '[3]#REF'!$A$1:$W$65
Name _PS3: '[5]#REF'!$A$1:$W$82
Name _PS3: '[2]#REF'!$A$1:$W$82
Name _PS3: '[3]#REF'!$A$1:$W$82
Name _PS4: '[5]#REF'!$A$1:$V$63
Name _PS4: '[2]#REF'!$A$1:$V$63
Name _PS4: '[3]#REF'!$A$1:$V$63

Sheet Considerações
B7: Principais Premissas | C7: Crescimento | D7: Margem Ebitda | E7: Investimento (Capex) | F7: Capital de giro
B8: Cenários
B9: =Output!B3 -> Base Case
B10: =Output!B4 -> Cliente Case
B11: =Output!B5 & " (Ainda a definir)" -> Stress Case (Ainda a definir)

Sheet Capa
C4: Unimed Rio
C6: Projeções Financeiras

Sheet Output
B2: SCENARIO | G2: 1 | I2: Check Scenario
B3: Base Case | G3: 1 | I3: Revenues, COGS & SG&A | L3: ='Revenues, COGS & SG&A'!C3 -> 1
B4: Cliente Case | G4: 2 | I4: Fixed Assets & CAPEX | L4: ='Fixed Assets & CAPEX'!C3 -> 1
B5: Stress Case | G5: 3 | I5: Working Capital | L5: ='Working Capital'!C3 -> 1
B8: SUMMARY
B9: R$ million - nominal | G9: 2010 | H9: =G9+1 -> 2011 | I9: =H9+1 -> 2012 | J9: =I9+1 -> 2013 | K9: =J9+1 -> 2014 | L9: =K9+1 -> 2015 | M9: =L9+1 -> 2016 | N9: =M9+1 -> 2017 | O9: =N9+1 -> 2018 | ... AB9: =AA9+1 -> 2031
B10: Net Revenues | G10: ='Income Statement'!H24 -> 2434971 | H10: ='Income Statement'!I24 -> 2853511 | I10: ='Income Statement'!J24 -> 3068721.7 | J10: ='Income Statement'!K24 -> 3352129.3 | K10: ='Income Statement'!L24 -> 3604529.7 | L10: ='Income Statement'!M24 -> 3881886.1 | M10: ='Income Statement'!N24 -> 4190073.4 | N10: ='Income Statement'!O24 -> 4520937.5 | ... AB10: ='Income Statement'!AC24 -> 12878274
B11: % Growth | G11: =(G10-F10)/F10 -> #DIV/0! | H11: =(H10-G10)/G10 -> 0.17188706 | I11: =(I10-H10)/H10 -> 0.075419627 | J11: =(J10-I10)/I10 -> 0.092353609 | K11: =(K10-J10)/J10 -> 0.075295561 | L11: =(L10-K10)/K10 -> 0.076946626 | M11: =(M10-L10)/L10 -> 0.07939113 | N11: =(N10-M10)/M10 -> 0.078963777 | ... AB11: =(AB10-AA10)/AA10 -> 0 | AE11: 2009 | AF11: 2010 | AG11: 2011 | AH11: 2012 | AI11: 2013 | AJ11: 2014 | AK11: 2015 | AO11: Cenário | AP11: Índice | AQ11: 2009 | AR11: 2010 | AS11: 2013 | AT11: =AS11+1 -> 2014 | AU11: =AT11+1 -> 2015 | AV11: =AU11+1 -> 2016 | AW11: =AV11+1 -> 2017 | AX11: =AW11+1 -> 2018 | AY11: =AX11+1 -> 2019 | AZ11: =AY11+1 -> 2020 | BA11: 2019 | BB11: 2020
B12: EBITDA | G12: ='Income Statement'!H42 -> 82461 | H12: ='Income Statement'!I42 -> 115501 | I12: ='Income Statement'!J42 -> 95584.45 | J12: ='Income Statement'!K42 -> 118167.81 | K12: ='Income Statement'!L42 -> 165665.86 | L12: ='Income Statement'!M42 -> 164205.03 | M12: ='Income Statement'!N42 -> 130003.15 | N12: ='Income Statement'!O42 -> 138513.19 | ... AB12: ='Income Statement'!AC42 -> 516528.38 | AD12: Ebitda | AE12: =G12 -> 82461 | AF12: =H12 -> 115501 | AG12: =I12 -> 95584.45 | AH12: =J12 -> 118167.81 | AI12: =K12 -> 165665.86 | AJ12: =L12 -> 164205.03 | AK12: =M12 -> 130003.15 | AO12: Base Case | AP12: Base Case | AS12: 0.040205585 | AT12: 0.04465238 | AU12: 0.045140839 | AV12: 0.046529054 | AW12: 0.047550553 | AX12: 0.048846226
B13: % Growth | G13: =(G12-F12)/F12 -> #DIV/0! | H13: =(H12-G12)/G12 -> 0.40067426 | I13: =(I12-H12)/H12 -> -0.17243617 | J13: =(J12-I12)/I12 -> 0.23626602 | K13: =(K12-J12)/J12 -> 0.40195422 | L13: =(L12-K12)/K12 -> -0.0088178805 | M13: =(M12-L12)/L12 -> -0.20828764 | N13: =(N12-M12)/M12 -> 0.065460259 | ... AB13: =(AB12-AA12)/AA12 -> -0.0067930673 | AD13: 2*Ebitda | AE13: =2*AE12 -> 164922 | AF13: =2*AF12 -> 231002 | AG13: =2*AG12 -> 191168.9 | AH13: =2*AH12 -> 236335.61 | AI13: =2*AI12 -> 331331.71 | AJ13: =2*AJ12 -> 328410.07 | AK13: =2*AK12 -> 260006.31 | AO13: Client Case | AP13: =B$25&" "&AO13 -> Variação NCG Client Case | AS13: -1130.3121 | AT13: -10886.227 | AU13: -12264.204 | AV13: -15929.103 | AW13: -14631.611 | AX13: -11863.965 | AY13: 2.3029296
B14: % EBITDA Margin | G14: =G12/G10 -> 0.03386529 | H14: =H12/H10 -> 0.040476802 | I14: =I12/I10 -> 0.031147969 | J14: =J12/J10 -> 0.035251566 | K14: =K12/K10 -> 0.045960463 | L14: =L12/L10 -> 0.042300322 | M14: =M12/M10 -> 0.031026462 | N14: =N12/N10 -> 0.030638158 | ... AB14: =AB12/AB10 -> 0.040108509 | AD14: Caixa | AE14: =G32 -> 119958 | AF14: =H32 -> 228486 | AG14: =I32 -> 149443.51 | AH14: =J32 -> 165864.86 | AI14: =K32 -> 120594.37 | AJ14: =L32 -> 70000 | AK14: =M32 -> 70000 | AO14: Stress Case | AP14: Stress Case | AS14: 0.03307451 | AT14: 0.032433557 | AU14: 0.031969457 | AV14: 0.031026462 | AW14: 0.030638158 | AX14: 0.030498388 | AY14: =O14 -> 0.030498388 | AZ14: =P14 -> 0.050102562
B15: Amortization Bancos | G15: n.a. | H15: n.a. | I15: ='ST Inv. & Debt'!H126 -> 0 | J15: ='ST Inv. & Debt'!I126 -> 0 | K15: ='ST Inv. & Debt'!J126 -> 0 | L15: ='ST Inv. & Debt'!K126 -> 0 | M15: ='ST Inv. & Debt'!L126 -> 0.33333333 | N15: ='ST Inv. & Debt'!M126 -> 0.33333333 | O15: ='ST Inv. & Debt'!N126 -> 0.33333333 | P15: ='ST Inv. & Debt'!O126 -> 0 | ... AB15: ='ST Inv. & Debt'!AA126 -> 0 | AD15: Dívida total permitida | AE15: =AE13+AE14 -> 284880 | AF15: =AF13+AF14 -> 459488 | AG15: =AG13+AG14 -> 340612.41 | AH15: =AH13+AH14 -> 402200.47 | AI15: =AI13+AI14 -> 451926.08 | AJ15: =AJ13+AJ14 -> 398410.07 | AK15: =AK13+AK14 -> 330006.31 | AP15: Corte Sugerido | AQ15: =$AX15 -> 0 | AR15: =$AX15 -> 0 | AY15: 0.8
B16: Net Profit | G16: ='Income Statement'!H81 -> 32615 | H16: ='Income Statement'!I81 -> 51805 | I16: ='Income Statement'!J81 -> 19970.898 | J16: ='Income Statement'!K81 -> 23388.519 | K16: ='Income Statement'!L81 -> 40022.884 | L16: ='Income Statement'!M81 -> 34441.552 | M16: ='Income Statement'!N81 -> 5830.7836 | N16: ='Income Statement'!O81 -> -24.583116 | ... AB16: ='Income Statement'!AC81 -> #VALUE!
B17: Capex | G17: nd | H17: nd | I17: ='Fixed Assets & CAPEX'!H37 -> 139000 | J17: ='Fixed Assets & CAPEX'!I37 -> 107863.74 | K17: ='Fixed Assets & CAPEX'!J37 -> 63272.849 | L17: ='Fixed Assets & CAPEX'!K37 -> 72311.827 | M17: ='Fixed Assets & CAPEX'!L37 -> 82642.088 | N17: ='Fixed Assets & CAPEX'!M37 -> 94448.101 | O17: ='Fixed Assets & CAPEX'!N37 -> 107940.69 | P17: ='Fixed Assets & CAPEX'!O104 -> 123360.79 | Q17: ='Fixed Assets & CAPEX'!P104 -> 121126.61 | R17: ='Fixed Assets & CAPEX'!Q104 -> 123021.31 | S17: ='Fixed Assets & CAPEX'!R104 -> 131556.8 | T17: ='Fixed Assets & CAPEX'!S104 -> 140020.37 | U17: ='Fixed Assets & CAPEX'!T104 -> 120210.67 | V17: ='Fixed Assets & CAPEX'!U104 -> 123891.03 | W17: ='Fixed Assets & CAPEX'!V104 -> 126169.65 | ... AB17: ='Fixed Assets & CAPEX'!AA104 -> 125658.84 | AO17: Base Case | AP17: Base Case | AQ17: n.a. | AR17: n.a. | AS17: 2.3505268 | AT17: 1.8981458 | AU17: 1.664438 | AV17: 1.3339471 | AW17: 1.0312661 | AX17: 0.73791208 | AY17: 8.3252499 | AZ17: 12.85502 | BA17: 43.347551 | BB17: #DIV/0!
B18: Current Portion of LT Debt | G18: ='Balance Sheet'!H50 -> 75294 | H18: ='Balance Sheet'!I50 -> 49121 | I18: ='Balance Sheet'!J50 -> 44928 | J18: ='Balance Sheet'!K50 -> 84248.825 | K18: ='Balance Sheet'!L50 -> 137426.11 | L18: ='Balance Sheet'!M50 -> 120481.63 | M18: ='Balance Sheet'!N50 -> 124575.83 | N18: ='Balance Sheet'!O50 -> 126614.73 | ... AB18: ='Balance Sheet'!AC50 -> 57171.388 | AD18: Total Debt permitido a 2x | AE18: =AE11 -> 2009 | AF18: =AF11 -> 2010 | AG18: =AG11 -> 2011 | AH18: =AH11 -> 2012 | AI18: =AI11 -> 2013 | AJ18: =AJ11 -> 2014 | AK18: =AK11 -> 2015 | AO18: Client Case | AP18: Covenant Sugerido | AQ18: n.a. | AR18: n.a. | AS18: 3 | AT18: 3 | AU18: 3 | AV18: 3 | AW18: 3 | AX18: 3 | AY18: 8.8590739 | AZ18: 14.847081 | BA18: 89.271082 | BB18: #DIV/0!
B19: Long Term Debt | G19: ='Balance Sheet'!H64 -> 135784 | H19: ='Balance Sheet'!I64 -> 344986 | I19: ='Balance Sheet'!J64 -> 391248 | J19: ='Balance Sheet'!K64 -> 436122.39 | K19: ='Balance Sheet'!L64 -> 327169.06 | L19: ='Balance Sheet'!M64 -> 239227.76 | M19: ='Balance Sheet'!N64 -> 151840.86 | N19: ='Balance Sheet'!O64 -> 67727.774 | ... AB19: ='Balance Sheet'!AC64 -> 41700 | AD19: =B3 -> Base Case | AE19: 164570 | AF19: 183465.55 | AG19: 170148.82 | AH19: 159491.35 | AI19: 162862.31 | AJ19: 186936.78 | AK19: 218723.07 | AO19: Stress Case | AP19: ="Interest Coverage "&AO19 -> Interest Coverage Stress Case | AQ19: n.a. | AR19: n.a. | AS19: 1.3667285 | AT19: 0.91197166 | AU19: 1.0356277 | AV19: 1.3761137 | AW19: 1.7752233 | AX19: 2.1959344 | AY19: 2.5172534 | AZ19: 2.9262704 | BA19: 3.6853073 | BB19: 4.7964766
B20: Revolving Leverage | G20: ='Balance Sheet'!H55 -> 0 | H20: ='Balance Sheet'!I55 -> 0 | I20: ='Balance Sheet'!J55 -> 0 | J20: ='Balance Sheet'!K55 -> 0 | K20: ='Balance Sheet'!L55 -> 0 | L20: ='Balance Sheet'!M55 -> 51880.553 | M20: ='Balance Sheet'!N55 -> 154768.37 | N20: ='Balance Sheet'!O55 -> 262913.99 | ... AB20: ='Balance Sheet'!AC55 -> #VALUE! | AD20: =B4 -> Cliente Case | AE20: 164570 | AF20: 204717.1 | AG20: 239998.33 | AH20: 259196.63 | AI20: 293350.95 | AJ20: 354049.09 | AK20: 428186.86 | AP20: Corte Sugerido | AQ20: =$AX20 -> 0 | AR20: =$AX20 -> 0
B21: Net Debt | G21: =G18+G19+G20-'Balance Sheet'!H13 -> 91120 | H21: =H18+H19+H20-'Balance Sheet'!I13 -> 165621 | I21: =I18+I19+I20-'Balance Sheet'!J13 -> 286732.49 | J21: =J18+J19+J20-'Balance Sheet'!K13 -> 354506.35 | K21: =K18+K19+K20-'Balance Sheet'!L13 -> 344000.8 | L21: =L18+L19+L20-'Balance Sheet'!M13 -> 341589.93 | M21: =M18+M19+M20-'Balance Sheet'!N13 -> 361185.06 | N21: =N18+N19+N20-'Balance Sheet'!O13 -> 387256.5 | ... AB21: =AB18+AB19+AB20-'Balance Sheet'!AC13 -> #VALUE! | AD21: =B5 -> Stress Case | AE21: 164570 | AF21: 167819.94 | AG21: 153977.52 | AH21: 144302.16 | AI21: 173477.33 | AJ21: 207217.01 | AK21: 231712.47
B22: Total Debt | H22: =H18+H19+H20 -> 394107 | I22: =I18+I19+I20 -> 436176 | J22: =J18+J19+J20 -> 520371.21 | K22: =K18+K19+K20 -> 464595.17 | L22: =L18+L19+L20 -> 411589.93 | M22: =M18+M19+M20 -> 431185.06 | N22: =N18+N19+N20 -> 457256.5 | O22: =O18+O19+O20 -> 488659.26 | ... AB22: =AB18+AB19+AB20 -> #VALUE!
B23: Net Debt / EBITDA (com revolving) | G23: =G21/G12 -> 1.1050072 | H23: =H21/H12 -> 1.4339356 | I23: =I21/I12 -> 2.9997818 | J23: =J21/J12 -> 3.0000248 | K23: =K21/K12 -> 2.0764738 | L23: =L21/L12 -> 2.0802647 | M23: =M21/M12 -> 2.7782792 | N23: =N21/N12 -> 2.7958095 | ... AB23: =AB21/AB12 -> #VALUE! | AO23: Base Case | AP23: ="Liquidez Seca "&AO23 -> Liquidez Seca Base Case | AQ23: 1.654467 | AR23: 3.0990813 | AS23: 2.792803 | AT23: 2.4669518 | AU23: 2.1859556 | AV23: 2.0513889 | AW23: 2.0297355 | AX23: 2.5673358 | AY23: 2.9183024 | AZ23: 3.6622641 | BA23: 4.0558025 | BB23: 4.4704877
B24: Total Debt / EBITDA (com revolving) | H24: =H22/H12 -> 3.4121523 | I24: =I22/I12 -> 4.5632527 | J24: =J22/J12 -> 4.4036631 | K24: =K22/K12 -> 2.8044111 | L24: =L22/L12 -> 2.506561 | M24: =M22/M12 -> 3.3167277 | N24: =N22/N12 -> 3.3011765 | O24: =O22/O12 -> 3.2825067 | ... AB24: =AB22/AB12 -> #VALUE!
B25: Variação NCG | G25: n.a. | H25: n.a. | I25: ='Cash Flow'!H19 -> -5892.988 | J25: ='Cash Flow'!I19 -> -7760.3803 | K25: ='Cash Flow'!J19 -> -6911.332 | L25: ='Cash Flow'!K19 -> -7594.6858 | M25: ='Cash Flow'!L19 -> -8438.9109 | N25: ='Cash Flow'!M19 -> -9059.8534 | O25: ='Cash Flow'!N19 -> -9863.94 | P25: ='Cash Flow'!P19 -> -11417.577 | Q25: ='Cash Flow'!Q19 -> -12255.468 | R25: ='Cash Flow'!R19 -> -13268.547 | S25: ='Cash Flow'!S19 -> -15723.948 | T25: ='Cash Flow'!T19 -> -17088 | U25: ='Cash Flow'!U19 -> -18570.384 | V25: ='Cash Flow'!V19 -> -20181.365 | W25: ='Cash Flow'!W19 -> -21932.098 | ... AB25: ='Cash Flow'!AB19 -> 0 | AO25: Client Case | AP25: ="Liquidez Seca "&AO25 -> Liquidez Seca Client Case | AQ25: 1.654467 | AR25: 2.9792809 | AS25: 2.6285731 | AT25: 2.1509618 | AU25: 1.9089283 | AV25: 1.9053959 | AW25: 2.1092385 | AX25: 2.9633391 | AY25: 2.8972543 | AZ25: 3.6083441 | BA25: 4.2549437 | BB25: 4.6023975
B26: Liquidez | G26: =G31/G49 -> 0.92612612 | H26: =H31/H49 -> 1.1874826 | I26: =I31/I49 -> 1.0511633 | J26: =J31/J49 -> 1.0210521 | K26: =K31/K49 -> 0.87970776 | L26: =L31/L49 -> 0.79225626 | M26: =M31/M49 -> 0.71191665 | N26: =N31/N49 -> 0.65308721 | ... AB26: =AB31/AB49 -> #VALUE! | AD26: =AD19 -> Base Case | AE26: 143212.5 | AF26: 164380.75 | AG26: 146656.67 | AH26: 131809.04 | AI26: 130925.44 | AJ26: 150685.12 | AK26: 177508.85 | AP26: Corte Sugerido | AQ26: =$AX26 -> 1.5 | AR26: =$AX26 -> 1.5 | AS26: 2 | AT26: 2 | AU26: 1.8 | AV26: 1.8 | AW26: 1.5 | AX26: 1.5
B27: (EBITDA)/(Juros + Amortização) | G27: =(G12)/(-G88-G120) -> #DIV/0! | H27: =(H12)/(-H88-H120) -> 2.819711 | I27: =(I12)/(-I88-I120) -> 0.90426485 | J27: =(J12)/(-J88-J120) -> 1.2753077 | K27: =(K12)/(-K88-K120) -> 1.2291494 | L27: =(L12)/(-L88-L120) -> 0.88350187 | M27: =(M12)/(-M88-M120) -> 0.59890068 | N27: =(N12)/(-N88-N120) -> 0.42207892 | ... AB27: =(AB12)/(-AB88-AB120) -> #VALUE! | AD27: =AD20 -> Cliente Case | AE27: 143212.5 | AF27: 180104.96 | AG27: 202039.08 | AH27: 211724.11 | AI27: 237908.05 | AJ27: 290148.92 | AK27: 354983.95
AD28: =AD21 -> Stress Case | AE28: 143212.5 | AF28: 147040.51 | AG28: 126752.77 | AH28: 110726.62 | AI28: 132607.99 | AJ28: 157912.76 | AK28: 176284.35 | AO28: Base Case | AP28: ="Net Debt / EBITDA "&AO28 -> Net Debt / EBITDA Base Case | AQ28: -0.92508577 | AR28: -0.31715496 | AS28: 2.3963706 | AT28: 2.3280127 | AU28: 1.87158 | AV28: 1.5310027 | AW28: 1.1431096 | AX28: 0.72027186 | AY28: 0.51839832 | AZ28: 0.086923138 | BA28: -0.34032976 | BB28: -0.75107533
B29: BALANCE SHEET | AO29: Client Case | AP29: ="Net Debt / EBITDA "&AO29 -> Net Debt / EBITDA Client Case | AQ29: -0.92508577 | AR29: -0.31715496 | AS29: 1.9214067 | AT29: 1.8837126 | AU29: 1.5973005 | AV29: 1.2760107 | AW29: 0.87276614 | AX29: 0.42758281 | AY29: 0.46919547 | AZ29: 0.021558984 | BA29: -0.45303542 | BB29: -1.0091994
B30: R$ million - nominal | G30: =+G$9 -> 2010 | H30: =+H$9 -> 2011 | I30: =+I$9 -> 2012 | J30: =+J$9 -> 2013 | K30: =+K$9 -> 2014 | L30: =+L$9 -> 2015 | M30: =+M$9 -> 2016 | N30: =+N$9 -> 2017 | ... AB30: =+AB$9 -> 2031 | AO30: Stress Case | AP30: ="Net Debt / EBITDA "&AO30 -> Net Debt / EBITDA Stress Case | AQ30: -0.92508577 | AR30: -0.31715496 | AS30: 4.9345766 | AT30: 4.7783112 | AU30: 4.4518329 | AV30: 4.0396359 | AW30: 3.5567187 | AX30: 3.0343066 | AY30: 2.6072214 | AZ30: 2.1268193 | BA30: 1.6246444 | BB30: 1.1614132
B31: Current Assets | G31: ='Balance Sheet'!H12 -> 375922 | H31: ='Balance Sheet'!I12 -> 601454 | I31: ='Balance Sheet'!J12 -> 550540.62 | J31: ='Balance Sheet'!K12 -> 604004.73 | K31: ='Balance Sheet'!L12 -> 591724.23 | L31: ='Balance Sheet'!M12 -> 577381.71 | M31: ='Balance Sheet'!N12 -> 617663.32 | N31: ='Balance Sheet'!O12 -> 660908.89 | ... AB31: ='Balance Sheet'!AC12 -> #VALUE! | AD31: =2800*(1-34%) -> 1848 | AP31: Corte Sugerido | AQ31: 0 | AR31: 0 | AS31: 2.6 | AT31: 2.6 | AU31: 2.2 | AV31: 2 | AW31: 1.5 | AX31: 1.5 | AY31: 1 | AZ31: 1 | BA31: 1 | BB31: 1
B32: ='Balance Sheet'!C13 -> Cash & Short Term Inv. | G32: ='Balance Sheet'!H13 -> 119958 | H32: ='Balance Sheet'!I13 -> 228486 | I32: ='Balance Sheet'!J13 -> 149443.51 | J32: ='Balance Sheet'!K13 -> 165864.86 | K32: ='Balance Sheet'!L13 -> 120594.37 | L32: ='Balance Sheet'!M13 -> 70000 | M32: ='Balance Sheet'!N13 -> 70000 | N32: ='Balance Sheet'!O13 -> 70000 | ... AB32: ='Balance Sheet'!AC13 -> #VALUE!
B33: ='Balance Sheet'!C15 -> Reserva Técnica | G33: ='Balance Sheet'!H15 -> 102022 | H33: ='Balance Sheet'!I15 -> 172303 | I33: ='Balance Sheet'!J15 -> 185298.03 | J33: ='Balance Sheet'!K15 -> 202410.97 | K33: ='Balance Sheet'!L15 -> 217651.62 | L33: ='Balance Sheet'!M15 -> 234399.17 | M33: ='Balance Sheet'!N15 -> 253008.39 | N33: ='Balance Sheet'!O15 -> 272986.89 | ... AB33: ='Balance Sheet'!AC15 -> 777626.33 | AO33: Base Case | AP33: ="EBITDA / INTEREST EXPENSE "&AO33 -> EBITDA / INTEREST EXPENSE Base Case | AQ33: n.a. | AR33: 3.9420497
B34: ='Balance Sheet'!C16 -> Créd. operações pl. de assist. à saúde | G34: ='Balance Sheet'!H16 -> 86898 | H34: ='Balance Sheet'!I16 -> 106236 | I34: ='Balance Sheet'!J16 -> 114248.28 | J34: ='Balance Sheet'!K16 -> 124799.52 | K34: ='Balance Sheet'!L16 -> 134196.37 | L34: ='Balance Sheet'!M16 -> 144522.33 | M34: ='Balance Sheet'!N16 -> 155996.12 | N34: ='Balance Sheet'!O16 -> 168314.16 | O34: ='Balance Sheet'!P16 -> 181725.46 | P34: ='Balance Sheet'!Q15 -> 318237.24 | Q34: ='Balance Sheet'!R15 -> 343414.91 | R34: ='Balance Sheet'!S15 -> 370440.27 | S34: ='Balance Sheet'!T15 -> 399699.65 | T34: ='Balance Sheet'!U15 -> 434373.59 | U34: ='Balance Sheet'!V15 -> 472055.5 | V34: ='Balance Sheet'!W15 -> 513006.32 | W34: ='Balance Sheet'!X15 -> 557509.62 | ... AB34: ='Balance Sheet'!AC15 -> 777626.33 | AO34: Client Case | AP34: ="EBITDA / INTEREST EXPENSE "&AO34 -> EBITDA / INTEREST EXPENSE Client Case | AQ34: n.a. | AR34: 5.0837439
B35: ='Balance Sheet'!C17 -> Despesas de comercialização diferidas | G35: ='Balance Sheet'!H17 -> 9839 | H35: ='Balance Sheet'!I17 -> 9480 | I35: ='Balance Sheet'!J17 -> 10194.978 | J35: ='Balance Sheet'!K17 -> 11136.521 | K35: ='Balance Sheet'!L17 -> 11975.052 | L35: ='Balance Sheet'!M17 -> 12896.492 | M35: ='Balance Sheet'!N17 -> 13920.359 | N35: ='Balance Sheet'!O17 -> 15019.563 | O35: ='Balance Sheet'!P17 -> 16216.324 | P35: ='Balance Sheet'!Q16 -> 196213.94 | Q35: ='Balance Sheet'!R16 -> 211737.62 | R35: ='Balance Sheet'!S16 -> 228400.51 | S35: ='Balance Sheet'!T16 -> 246440.82 | T35: ='Balance Sheet'!U16 -> 267819.56 | U35: ='Balance Sheet'!V16 -> 291052.9 | V35: ='Balance Sheet'!W16 -> 316301.74 | W35: ='Balance Sheet'!X16 -> 343740.92 | ... AB35: ='Balance Sheet'!AC16 -> 479457.18 | AO35: Stress Case | AP35: ="EBITDA / INTEREST EXPENSE "&AO35 -> EBITDA / INTEREST EXPENSE Stress Case | AQ35: n.a. | AR35: 4.2920817
B36: ='Balance Sheet'!C18 -> Títulos e créditos a receber | G36: ='Balance Sheet'!H18 -> 45149 | H36: ='Balance Sheet'!I18 -> 52275 | I36: ='Balance Sheet'!J18 -> 56217.561 | J36: ='Balance Sheet'!K18 -> 61409.456 | K36: ='Balance Sheet'!L18 -> 66033.315 | L36: ='Balance Sheet'!M18 -> 71114.356 | M36: ='Balance Sheet'!N18 -> 76760.205 | N36: ='Balance Sheet'!O18 -> 82821.481 | O36: ='Balance Sheet'!P18 -> 89420.711 | P36: ='Balance Sheet'!Q20 -> 0 | Q36: ='Balance Sheet'!R20 -> 0 | R36: ='Balance Sheet'!S20 -> 0 | S36: ='Balance Sheet'!T20 -> 0 | T36: ='Balance Sheet'!U20 -> 0 | U36: ='Balance Sheet'!V20 -> 0 | V36: ='Balance Sheet'!W20 -> 0 | W36: ='Balance Sheet'!X20 -> 0 | ... AB36: ='Balance Sheet'!AC20 -> 0 | AP36: Corte Sugerido | AQ36: =$AX36 -> 0 | AR36: =$AX36 -> 0 | AS36: =$AX36 -> 0 | AT36: =$AX36 -> 0 | AU36: =$AX36 -> 0 | AV36: =$AX36 -> 0 | AW36: =$AX36 -> 0
B37: ='Balance Sheet'!C19 -> Outros valores e bens | G37: ='Balance Sheet'!H19 -> 12056 | H37: ='Balance Sheet'!I19 -> 32674 | I37: ='Balance Sheet'!J19 -> 35138.261 | J37: ='Balance Sheet'!K19 -> 38383.406 | K37: ='Balance Sheet'!L19 -> 41273.506 | L37: ='Balance Sheet'!M19 -> 44449.363 | M37: ='Balance Sheet'!N19 -> 47978.248 | N37: ='Balance Sheet'!O19 -> 51766.792 | O37: ='Balance Sheet'!P19 -> 55891.579
B38: Long-Term Assets | G38: ='Balance Sheet'!H27 -> 741463 | H38: ='Balance Sheet'!I27 -> 708901 | I38: ='Balance Sheet'!J27 -> 708901 | J38: ='Balance Sheet'!K27 -> 708901 | K38: ='Balance Sheet'!L27 -> 708901 | L38: ='Balance Sheet'!M27 -> 708901 | M38: ='Balance Sheet'!N27 -> 708901 | N38: ='Balance Sheet'!O27 -> 708901 | ... AB38: ='Balance Sheet'!AC27 -> 708901
B39: ='Balance Sheet'!C28 -> Ativo Fiscal Diferido | G39: ='Balance Sheet'!H28 -> 6460 | H39: ='Balance Sheet'!I28 -> 8368 | I39: ='Balance Sheet'!J28 -> 8368 | J39: ='Balance Sheet'!K28 -> 8368 | K39: ='Balance Sheet'!L28 -> 8368 | L39: ='Balance Sheet'!M28 -> 8368 | M39: ='Balance Sheet'!N28 -> 8368 | N39: ='Balance Sheet'!O28 -> 8368 | ... AB39: ='Balance Sheet'!AC28 -> 8368 | AO39: Base Case | AP39: ="Total Debt / (EBITDA+WCC) "&AO39 -> Total Debt / (EBITDA+WCC) Base Case | AQ39: n.a. | AR39: 0.17376374 | AS39: 3.4901979 | AT39: 2.6701663 | AU39: 2.011435 | AV39: 1.592421 | AW39: 1.1369846 | AX39: 0.44815481 | AY39: 0.56705325 | AZ39: 0.19455969 | BA39: 0.028855506 | BB39: 0.025983266
B40: ='Balance Sheet'!C29 -> Valores e bens | G40: ='Balance Sheet'!H29 -> 45783 | H40: ='Balance Sheet'!I29 -> 65262 | I40: ='Balance Sheet'!J29 -> 65262 | J40: ='Balance Sheet'!K29 -> 65262 | K40: ='Balance Sheet'!L29 -> 65262 | L40: ='Balance Sheet'!M29 -> 65262 | M40: ='Balance Sheet'!N29 -> 65262 | N40: ='Balance Sheet'!O29 -> 65262 | O40: ='Balance Sheet'!P29 -> 65262
B41: ='Balance Sheet'!C30 -> Conta-corrente com cooperados | G41: ='Balance Sheet'!H30 -> 689220 | H41: ='Balance Sheet'!I30 -> 635271 | I41: ='Balance Sheet'!J30 -> 635271 | J41: ='Balance Sheet'!K30 -> 635271 | K41: ='Balance Sheet'!L30 -> 635271 | L41: ='Balance Sheet'!M30 -> 635271 | M41: ='Balance Sheet'!N30 -> 635271 | N41: ='Balance Sheet'!O30 -> 635271 | O41: ='Balance Sheet'!P30 -> 635271
B42: ='Balance Sheet'!C31 -> Bens destinados a venda | G42: ='Balance Sheet'!H31 -> 0 | H42: ='Balance Sheet'!I31 -> 0 | I42: ='Balance Sheet'!J31 -> 0 | J42: ='Balance Sheet'!K31 -> 0 | K42: ='Balance Sheet'!L31 -> 0 | L42: ='Balance Sheet'!M31 -> 0 | M42: ='Balance Sheet'!N31 -> 0 | N42: ='Balance Sheet'!O31 -> 0 | O42: ='Balance Sheet'!P31 -> 0 | P42: ='Balance Sheet'!Q29 -> 65262 | Q42: ='Balance Sheet'!R29 -> 65262 | R42: ='Balance Sheet'!S29 -> 65262 | S42: ='Balance Sheet'!T29 -> 65262 | T42: ='Balance Sheet'!U29 -> 65262 | U42: ='Balance Sheet'!V29 -> 65262 | V42: ='Balance Sheet'!W29 -> 65262 | W42: ='Balance Sheet'!X29 -> 65262 | ... AB42: ='Balance Sheet'!AC29 -> 65262 | AO42: Client Case | AP42: ="Total Debt / (EBITDA+WCC) "&AO42 -> Total Debt / (EBITDA+WCC) Client Case | AQ42: n.a. | AR42: 0.26220802 | AS42: 3.7083104 | AT42: 3.3811167 | AU42: 3.2020542 | AV42: 2.2690903 | AW42: 1.4673449 | AX42: 0.57972032 | AY42: 0.48128469 | AZ42: 0.099238699 | BA42: 0.021320086 | BB42: 0.017762639
B43: Permanent | G43: ='Balance Sheet'!H34 -> 297589 | H43: ='Balance Sheet'!I34 -> 407811 | I43: ='Balance Sheet'!J34 -> 518804.4 | J43: ='Balance Sheet'!K34 -> 578804.4 | K43: ='Balance Sheet'!L34 -> 578804.4 | L43: ='Balance Sheet'!M34 -> 578804.4 | M43: ='Balance Sheet'!N34 -> 578804.4 | N43: ='Balance Sheet'!O34 -> 578804.4 | ... AB43: ='Balance Sheet'!AC34 -> 578804.4 | AO43: Stress Case | AP43: ="Total Debt / (EBITDA+WCC) "&AO43 -> Total Debt / (EBITDA+WCC) Stress Case | AQ43: n.a. | AR43: 0.18284319 | AS43: 7.5960487 | AT43: 6.5554055 | AU43: 6.1424919 | AV43: 5.4313143 | AW43: 4.7642196 | AX43: 2.1867103 | AY43: 2.2437947 | AZ43: 1.8542284 | BA43: 1.4466947 | BB43: 1.0648172
...

Sheet Revenues, COGS & SG&A
A2: 1 | B2: Base Case | C2: Scenario
A3: 2 | B3: Client Case | C3: =Output!G2 -> 1
A4: 3 | B4: Stress Case
B5: Last Completed Period | C5: 40908
B7: REVENUES | D7: =+EOMONTH(E7,-12) -> 39447 | E7: =+EOMONTH(F7,-12) -> 39813 | F7: =+EOMONTH(G7,-12) -> 40178 | G7: =+EOMONTH(H7,-12) -> 40543 | H7: =C5 -> 40908 | I7: =+EOMONTH(H7,12) -> 41274 | J7: =+EOMONTH(I7,12) -> 41639 | K7: =+EOMONTH(J7,12) -> 42004 | L7: =+EOMONTH(K7,12) -> 42369 | M7: =+EOMONTH(L7,12) -> 42735 | N7: =+EOMONTH(M7,12) -> 43100 | O7: =+EOMONTH(N7,12) -> 43465 | P7: =+EOMONTH(O7,12) -> 43830 | ... AC7: =+EOMONTH(AB7,12) -> 48579
B8: R$ thousand
B10: GROSS REVENUES | C10: HISTORICO | G10: =Premissas!B9 -> 2434971 | H10: =Premissas!C9 -> 2853511 | I10: =H10*(1+CHOOSE($C$3,I11,I12,I13)) -> 3068721.7 | J10: =I10*(1+CHOOSE($C$3,J11,J12,J13)) -> 3352129.3 | K10: =J10*(1+CHOOSE($C$3,K11,K12,K13)) -> 3604529.7 | L10: =K10*(1+CHOOSE($C$3,L11,L12,L13)) -> 3881886.1 | M10: =L10*(1+CHOOSE($C$3,M11,M12,M13)) -> 4190073.4 | N10: =M10*(1+CHOOSE($C$3,N11,N12,N13)) -> 4520937.5 | O10: =N10*(1+CHOOSE($C$3,O11,O12,O13)) -> 4881166.6 | P10: =O10*(1+CHOOSE($C$3,P11,P12,P13)) -> 5270328.7 | ... AC10: =AB10*(1+CHOOSE($C$3,AC11,AC12,AC13)) -> 12878274
B11: Receita | I11: =Anual!T20/100 -> 0.075419627 | J11: =Anual!U20/100 -> 0.092353609 | K11: =Anual!V20/100 -> 0.075295561 | L11: =Anual!W20/100 -> 0.076946626 | M11: =Anual!X20/100 -> 0.07939113 | N11: =Anual!Y20/100 -> 0.078963777 | O11: =Anual!Z20/100 -> 0.079680178 | P11: =Anual!AA20/100 -> 0.079727286 | ... AC11: =Anual!AN20/100 -> 0
G12: crec | I12: =I11 -> 0.075419627 | J12: =J11 -> 0.092353609 | K12: =K11 -> 0.075295561 | L12: =L11 -> 0.076946626 | M12: =M11 -> 0.07939113 | N12: =N11 -> 0.078963777 | O12: =O11 -> 0.079680178 | P12: =P11 -> 0.079727286 | ... AD12: =AD11 -> 0
I13: 0.07 | J13: 0.07 | K13: 0.07 | L13: 0.07 | M13: 0.07 | N13: 0.07 | O13: 0.07 | P13: 0.07 | Q13: 0.07 | R13: =R12 -> 0.078695954 | S13: =S12 -> 0.078985405 | T13: =T12 -> 0.08675 | U13: =U12 -> 0.08675 | V13: =V12 -> 0.08675 | W13: =W12 -> 0.08675 | X13: =X12 -> 0.08675 | Y13: =Y12 -> 0.08675 | ... AC13: =AC12 -> 0
B23: DEVOLUÇÔES | I23: =I24*I10 -> 0 | J23: =J24*J10 -> 0 | K23: =K24*K10 -> 0 | L23: =L24*L10 -> 0 | M23: =M24*M10 -> 0 | N23: =N24*N10 -> 0 | O23: =O24*O10 -> 0 | P23: =P24*P10 -> 0 | ... AC23: =AC24*AC10 -> 0
B24: % Gross | D24: =IF(D10>0,D23/D10,0) -> 0 | E24: =IF(E10>0,E23/E10,0) -> 0 | F24: =IF(F10>0,F23/F10,0) -> 0 | G24: =IF(G10>0,G23/G10,0) -> 0 | H24: =IF(H10>0,H23/H10,0) -> 0 | I24: =AVERAGE(G24:H24) -> 0 | J24: =I24 -> 0 | K24: =J24 -> 0 | L24: =K24 -> 0 | M24: =L24 -> 0 | N24: =M24 -> 0 | O24: =N24 -> 0 | P24: =O24 -> 0 | Q24: =P24 -> 0 | ... AC24: =AB24 -> 0
B27: IMPOSTOS
B28: % Gross | D28: =IF(D13>0,D27/D13,0) -> 0 | E28: =IF(E13>0,E27/E13,0) -> 0 | F28: =IF(F13>0,F27/F13,0) -> 0 | G28: =IF(G10>0,G27/(G10-G23),0) -> 0 | H28: =IF(H10>0,H27/(H10-H23),0) -> 0 | I28: =CHOOSE($C$3,I30,I31,I32) -> 0 | J28: =CHOOSE($C$3,J30,J31,J32) -> 0 | K28: =CHOOSE($C$3,K30,K31,K32) -> 0 | L28: =CHOOSE($C$3,L30,L31,L32) -> 0 | M28: =CHOOSE($C$3,M30,M31,M32) -> 0 | N28: =CHOOSE($C$3,N30,N31,N32) -> 0 | O28: =CHOOSE($C$3,O30,O31,O32) -> 0 | P28: =CHOOSE($C$3,P30,P31,P32) -> 0 | ... AC28: =CHOOSE($C$3,AC30,AC31,AC32) -> 0
I30: 0 | J30: 0 | K30: 0 | L30: 0 | M30: 0 | N30: 0 | O30: 0 | P30: 0 | Q30: 0 | R30: 0 | S30: 0 | T30: 0 | U30: 0 | V30: 0 | W30: 0 | X30: 0 | Y30: 0 | Z30: 0 | AA30: 0 | AB30: 0 | AC30: 0
I31: 0 | J31: 0 | K31: 0 | L31: 0 | M31: 0 | N31: 0 | O31: 0 | P31: 0 | Q31: 0 | R31: 0 | S31: 0 | T31: 0 | U31: 0 | V31: 0 | W31: 0 | X31: 0 | Y31: 0 | Z31: 0 | AA31: 0 | AB31: 0 | AC31: 0
I32: 0 | J32: 0 | K32: 0 | L32: 0 | M32: 0 | N32: 0 | O32: 0 | P32: 0 | Q32: 0 | R32: 0 | S32: 0 | T32: 0 | U32: 0 | V32: 0 | W32: 0 | X32: 0 | Y32: 0 | Z32: 0 | AA32: 0 | AB32: 0 | AC32: 0
B34: RECEITA LÍQUIDA | D34: =D10-D23 -> 0 | E34: =E10-E23 -> 0 | F34: =F10-F23 -> 0 | G34: =G10-G23-G27 -> 2434971 | H34: =H10-H23-H27 -> 2853511 | I34: =I10-I23-I27 -> 3068721.7 | J34: =J10-J23-J27 -> 3352129.3 | K34: =K10-K23-K27 -> 3604529.7 | L34: =L10-L23-L27 -> 3881886.1 | M34: =M10-M23-M27 -> 4190073.4 | N34: =N10-N23-N27 -> 4520937.5 | ... AC34: =AC10-AC23-AC27 -> 12878274
B35: % Gross | D35: =IF(D10>0,D34/D10,0) -> 0 | E35: =IF(E10>0,E34/E10,0) -> 0 | F35: =IF(F10>0,F34/F10,0) -> 0 | G35: =IF(G10>0,G34/G10,0) -> 1 | H35: =IF(H$10>0,H34/H$10,0) -> 1 | I35: =H35 -> 1 | J35: =IF(J10>0,J34/J10,0) -> 1 | K35: =IF(K10>0,K34/K10,0) -> 1 | L35: =IF(L10>0,L34/L10,0) -> 1 | M35: =IF(M10>0,M34/M10,0) -> 1 | N35: =IF(N10>0,N34/N10,0) -> 1 | O35: =IF(O10>0,O34/O10,0) -> 1 | P35: =IF(P10>0,P34/P10,0) -> 1 | Q35: =IF(Q10>0,Q34/Q10,0) -> 1 | ... AC35: =IF(AC10>0,AC34/AC10,0) -> 1
B37: (Ganho de escala *0,99%)
B38: CUSTOS | G38: =-Premissas!B18 -> 1897818 | H38: =-Premissas!C18 -> 2250776 | I38: =I41+I46 -> 2425322.3 | J38: =J41+J46 -> 2652824.4 | K38: =K41+K46 -> 2825774.9 | L38: =L41+L46 -> 3061587.4 | M38: =M41+M46 -> 3356477.9 | N38: =N41+N46 -> 3628553.9 | O38: =O41+O46 -> 3924326.9 | P38: =P41+P46 -> 4140696.6 | ... AC38: =AC41+AC46 -> 10196585
G39: =G38/G34 -> 0.77940066 | H39: , | I39: =I38/I34 -> 0.79033633 | J39: =J38/J34 -> 0.79138487 | K39: =K38/K34 -> 0.78395107 | L39: =L38/L34 -> 0.78868552 | M39: =M38/M34 -> 0.80105467 | N39: =N38/N34 -> 0.80261094 | O39: =O38/O34 -> 0.80397315 | P39: =P38/P34 -> 0.78566192 | ... AC39: =AC38/AC34 -> 0.79176641
B41: Custo Variável | D41: =IF(D$10>0,D38/D$10,0) -> 0 | E41: =IF(E$34>0,E38/E$34,0) -> 0 | F41: =IF(F$34>0,F38/F$34,0) -> 0 | G41: =G38 -> 1897818 | H41: =H38 -> 2250776 | I41: =CHOOSE($C$3,I42,I43,I44)*(I34) -> 2425322.3 | J41: =CHOOSE($C$3,J42,J43,J44)*(J34) -> 2652824.4 | K41: =CHOOSE($C$3,K42,K43,K44)*(K34) -> 2825774.9 | L41: =CHOOSE($C$3,L42,L43,L44)*(L34) -> 3061587.4 | M41: =CHOOSE($C$3,M42,M43,M44)*(M34) -> 3356477.9 | N41: =CHOOSE($C$3,N42,N43,N44)*(N34) -> 3628553.9 | O41: =CHOOSE($C$3,O42,O43,O44)*(O34) -> 3924326.9 | P41: =CHOOSE($C$3,P42,P43,P44)*(P34) -> 4140696.6 | ... AC41: =CHOOSE($C$3,AC42,AC43,AC44)*(AC34) -> 10196585
G42: =G38/G34 -> 0.77940066 | H42: =H38/H34 -> 0.78877425 | I42: 0.79033633 | J42: 0.79138487 | K42: 0.78395107 | L42: 0.78868552 | M42: 0.80105467 | N42: 0.80261094 | O42: 0.80397315 | P42: 0.78566192 | Q42: =AVERAGE(O42:P42) -> 0.79481754 | R42: =AVERAGE(P42:Q42) -> 0.79023973 | S42: =AVERAGE(Q42:R42) -> 0.79252863 | T42: =AVERAGE(R42:S42) -> 0.79138418 | U42: =AVERAGE(S42:T42) -> 0.79195641 | V42: =AVERAGE(T42:U42) -> 0.79167029 | W42: =AVERAGE(U42:V42) -> 0.79181335 | X42: =AVERAGE(V42:W42) -> 0.79174182 | ... AC42: =AVERAGE(AA42:AB42) -> 0.79176641
I43: =I42 -> 0.79033633 | J43: =J42 -> 0.79138487 | K43: =K42 -> 0.78395107 | L43: =L42 -> 0.78868552 | M43: =M42 -> 0.80105467 | N43: =N42 -> 0.80261094 | O43: =O42 -> 0.80397315 | P43: =P42 -> 0.78566192 | ... AC43: =AC42 -> 0.79176641
I44: =I43 -> 0.79033633 | J44: 0.3527 | K44: 0.3869 | L44: 0.4164 | M44: 0.4528 | N44: 0.5032 | O44: 0.5 | P44: =P43 -> 0.78566192 | Q44: =Q43 -> 0.79481754 | R44: =R43 -> 0.79023973 | S44: =S43 -> 0.79252863 | T44: =T43 -> 0.79138418 | U44: =U43 -> 0.79195641 | V44: =V43 -> 0.79167029 | W44: =W43 -> 0.79181335 | ... AC44: =AC43 -> 0.79176641
B46: Custo Fixo | I46: =H46*(1+Anual!T41/100)*H41 -> 0 | J46: =I46*(1+Anual!U41/100) -> 0 | K46: =J46*(1+Anual!V41/100) -> 0 | L46: =K46*(1+Anual!W41/100) -> 0 | M46: =L46*(1+Anual!X41/100) -> 0 | N46: =M46*(1+Anual!Y41/100) -> 0 | O46: =N46*(1+Anual!Z41/100) -> 0 | P46: =O46*(1+Anual!AA41/100) -> 0 | Q46: =P46*(1+Anual!AB41/100) -> 0 | ... AC46: =AB46*(1+Anual!AN41/100) -> 0
B48: SG&A | G48: =-Premissas!B28 -> 492128 | H48: =-Premissas!C28 -> 535439 | I48: =I52 -> 575821.61 | J48: =J52 -> 629000.81 | K48: =K52 -> 676361.78 | L48: =L52 -> 728405.54 | M48: =M52 -> 786234.48 | N48: =N52 -> 848318.52 | O48: =O52 -> 915912.69 | P48: =P52 -> 988935.93 | ... U48: =U52 -> 1466932.8 | V48: =V52-V57 -> 1470298.2 | W48: =W52-W57 -> 1606315.5 | X48: =X52-X57 -> 1756207.3 | Y48: =Y52-Y57 -> 1918760.6 | Z48: =Z52-Z57 -> 2095642.4 | AA48: =AA52-AA57 -> 2289053.3 | AB48: =AB52-AB57 -> 2290848.5 | AC48: =AC52-AC57 -> 2290070.2
B49: % Gross | D49: =D48/D34 -> #DIV/0! | E49: =E48/E34 -> #DIV/0! | F49: =F48/F34 -> #DIV/0! | G49: =G48/G34 -> 0.20210836 | H49: =H48/H34 -> 0.18764217 | I49: =I48/I34 -> 0.18764217 | J49: =J48/J34 -> 0.18764217 | K49: =K48/K34 -> 0.18764217 | ... AC49: =AC48/AC34 -> 0.17782431
G52: =G48 -> 492128 | H52: =H48 -> 535439 | I52: =CHOOSE($C$3,I53,I54,I55)*(I34) -> 575821.61 | J52: =CHOOSE($C$3,J53,J54,J55)*(J34) -> 629000.81 | K52: =CHOOSE($C$3,K53,K54,K55)*(K34) -> 676361.78 | L52: =CHOOSE($C$3,L53,L54,L55)*(L34) -> 728405.54 | M52: =CHOOSE($C$3,M53,M54,M55)*(M34) -> 786234.48 | N52: =CHOOSE($C$3,N53,N54,N55)*(N34) -> 848318.52 | O52: =CHOOSE($C$3,O53,O54,O55)*(O34) -> 915912.69 | P52: =CHOOSE($C$3,P53,P54,P55)*(P34) -> 988935.93 | ... AC52: =CHOOSE($C$3,AC53,AC54,AC55)*(AC34) -> 2416507.3
G53: =G48/G34 -> 0.20210836 | H53: =H48/H34 -> 0.18764217 | I53: =H53 -> 0.18764217 | J53: =AVERAGE(H53:I53) -> 0.18764217 | K53: =AVERAGE(I53:J53) -> 0.18764217 | L53: =AVERAGE(J53:K53) -> 0.18764217 | M53: =AVERAGE(K53:L53) -> 0.18764217 | N53: =AVERAGE(L53:M53) -> 0.18764217 | O53: =AVERAGE(M53:N53) -> 0.18764217 | P53: =AVERAGE(N53:O53) -> 0.18764217 | Q53: =AVERAGE(O53:P53) -> 0.18764217 | ... AC53: =AVERAGE(AA53:AB53) -> 0.18764217
I54: =I53 -> 0.18764217 | J54: =J53 -> 0.18764217 | K54: =K53 -> 0.18764217 | L54: =L53 -> 0.18764217 | M54: =M53 -> 0.18764217 | N54: =N53 -> 0.18764217 | O54: =O53 -> 0.18764217 | P54: =P53 -> 0.18764217 | ... AC54: =AC53 -> 0.18764217
I55: =I54 -> 0.18764217 | J55: =J54 -> 0.18764217 | K55: =K54 -> 0.18764217 | L55: =L54 -> 0.18764217 | M55: =M54 -> 0.18764217 | N55: =N54 -> 0.18764217 | O55: =O54 -> 0.18764217 | P55: =P54 -> 0.18764217 | ... AC55: =AC54 -> 0.18764217
B57: (+) Depreciação | G57: 37436 | H57: 48205 | I57: ='Fixed Assets & CAPEX'!H77 -> 28006.6 | J57: ='Fixed Assets & CAPEX'!I77 -> 47863.743 | K57: ='Fixed Assets & CAPEX'!J77 -> 63272.849 | L57: ='Fixed Assets & CAPEX'!K77 -> 72311.827 | M57: ='Fixed Assets & CAPEX'!L77 -> 82642.088 | N57: ='Fixed Assets & CAPEX'!M77 -> 94448.101 | O57: ='Fixed Assets & CAPEX'!N77 -> 107940.69 | P57: ='Fixed Assets & CAPEX'!O77 -> 123360.79 | ... AC57: ='Fixed Assets & CAPEX'!AB77 -> 126437.15
B58: % Gross | D58: =D57/D34 -> #DIV/0! | E58: =E57/E34 -> #DIV/0! | F58: =F57/F34 -> #DIV/0! | G58: =G57/G34 -> 0.01537431 | H58: =H57/H34 -> 0.016893224 | I58: =I57/I34 -> 0.009126471 | J58: =J57/J34 -> 0.014278609 | K58: =K57/K34 -> 0.017553704 | ... AC58: =AC57/AC34 -> 0.009817864
B60: (+) Amortização | I60: ='Goodwill, Taxes & Div.'!H31 -> 0 | J60: ='Goodwill, Taxes & Div.'!I31 -> 0 | K60: ='Goodwill, Taxes & Div.'!J31 -> 0 | L60: ='Goodwill, Taxes & Div.'!K31 -> 0 | M60: ='Goodwill, Taxes & Div.'!L31 -> 0 | N60: ='Goodwill, Taxes & Div.'!M31 -> 0 | O60: ='Goodwill, Taxes & Div.'!N31 -> 0 | P60: ='Goodwill, Taxes & Div.'!O31 -> 0 | ... AC60: ='Goodwill, Taxes & Div.'!AB31 -> 0
B61: % Gross | D61: =D60/#REF! -> #REF! | E61: =E60/#REF! -> #REF! | F61: =F60/#REF! -> #REF! | G61: =G60/#REF! -> #REF! | H61: =G61 -> #REF! | I61: =H61 -> #REF! | J61: =I61 -> #REF! | K61: =J61 -> #REF! | L61: =K61 -> #REF! | M61: =L61 -> #REF! | N61: =M61 -> #REF! | O61: =N61 -> #REF! | ... AC61: =AB61 -> #REF!
B64: EBITDA | D64: =D34-D38-D48+D57 -> 0 | E64: =E34-E38-E48+E57 -> 0 | F64: =F34-F38-F48+F57 -> 0 | G64: =G34-G38-G48+G57 -> 82461 | H64: =H34-H38-H48+H57 -> 115501 | I64: =I34-I38-I48+I57 -> 95584.45 | J64: =J34-J38-J48+J57 -> 118167.81 | K64: =K34-K38-K48+K57 -> 165665.86 | ... AC64: =AC34-AC38-AC48+AC57 -> 518056.22
B65: EBITDA Margin | D65: =D64/D34 -> #DIV/0! | E65: =E64/E34 -> #DIV/0! | F65: =F64/F34 -> #DIV/0! | G65: =G64/G34 -> 0.03386529 | H65: =H64/H34 -> 0.040476802 | I65: =I64/I34 -> 0.031147969 | J65: =J64/J34 -> 0.035251566 | K65: =K64/K34 -> 0.045960463 | ... AC65: =AC64/AC34 -> 0.040227146
I67: 0.071168652 | J67: 0.098047706 | K67: 0.1577181 | L67: 0.19428325 | M67: 0.24390214 | N67: 0.31483632
...

Sheet Premissas
A1: Premissas
A3: Receitas
B4: 2010 | C4: 2011 | D4: =C4+1 -> 2012 | E4: =D4+1 -> 2013 | F4: =E4+1 -> 2014 | G4: =F4+1 -> 2015 | H4: =G4+1 -> 2016 | I4: =H4+1 -> 2017 | J4: =I4+1 -> 2018
A6: Contraprest. efetivas de plano de assist. à saúde | B6: 2109847 | C6: 2461029
A7: Outras receitas oper. de assist. à saúde não relac. com planos de saúde da operadora | B7: 325124 | C7: 392482
A9: Total | B9: =SUM(B6:B7) -> 2434971 | C9: =SUM(C6:C7) -> 2853511
A12: Eventos conhecidos ou avisados | B12: -1573150 | C12: -2046013
A13: Recuperação de eventos conhecidos ou avisados | B13: 8133 | C13: 209233
A14: Outras Recuperações/Ressarcimentos/Deduções de | B14: 7741 | C14: 15434
A15: Variação da provisão de eventos ocorridos e não avisados | B15: -42210 | C15: -56528
A16: Outras despesas oper. de assist. à saúde não relac. com planos de saúde da operadora | B16: -298332 | C16: -372902
A18: Eventos indenizáveis líquidos | B18: =SUM(B12:B16) -> -1897818 | C18: =SUM(C12:C16) -> -2250776
A21: Despesas de comercialização | B21: -142210 | C21: -183324
A22: Despesas administrativas | B22: -300484 | C22: -314590
A23: Outras receitas operacionais | B23: 4774 | C23: 4789
A24: Outras despesas operacionais | B24: =SUM(B25:B27) -> -54208 | C24: =SUM(C25:C27) -> -42314
A25: Provisão para perdas sobre créditos | B25: -42990 | C25: -26184
A26: Provisão para contingências - operacional | B26: -1406 | C26: -7179
A27: Outras | B27: -9812 | C27: -8951
A28: Total | B28: =SUM(B21:B24) -> -492128 | C28: =SUM(C21:C24) -> -535439

Sheet Income Statement
A7: =+A6+1 -> 1 | C7: INCOME STATEMENT | E7: ='Revenues, COGS & SG&A'!D7 -> 39447 | F7: ='Revenues, COGS & SG&A'!E7 -> 39813 | G7: ='Revenues, COGS & SG&A'!F7 -> 40178 | H7: ='Revenues, COGS & SG&A'!G7 -> 40543 | I7: ='Revenues, COGS & SG&A'!H7 -> 40908 | J7: ='Revenues, COGS & SG&A'!I7 -> 41274 | K7: ='Revenues, COGS & SG&A'!J7 -> 41639 | L7: ='Revenues, COGS & SG&A'!K7 -> 42004 | ... AD7: ='Revenues, COGS & SG&A'!AC7 -> 48579
A8: =+A7+1 -> 2 | C8: R$ thousand
A9: =+A8+1 -> 3
A10: =+A9+1 -> 4 | B10: + | C10: GROSS REVENUES | E10: ='Revenues, COGS & SG&A'!D10 -> 0 | F10: ='Revenues, COGS & SG&A'!E10 -> 0 | G10: ='Revenues, COGS & SG&A'!F10 -> 0 | H10: ='Revenues, COGS & SG&A'!G10 -> 2434971 | I10: ='Revenues, COGS & SG&A'!H10 -> 2853511 | J10: ='Revenues, COGS & SG&A'!I10 -> 3068721.7 | K10: ='Revenues, COGS & SG&A'!J10 -> 3352129.3 | L10: ='Revenues, COGS & SG&A'!K10 -> 3604529.7 | ... AD10: ='Revenues, COGS & SG&A'!AC10 -> 12878274
A11: =+A10+1 -> 5 | C11: Gross Revenues
A12: =+A11+1 -> 6 | C12: Item 2
A13: =+A12+1 -> 7 | C13: Item 3
A14: =+A13+1 -> 8 | C14: Item 4
A15: =+A14+1 -> 9 | C15: Item 5
A16: =+A15+1 -> 10
A17: =+A16+1 -> 11 | B17: (-) | C17: Deductions | F17: ='Revenues, COGS & SG&A'!D23+'Revenues, COGS & SG&A'!#REF! -> #REF! | G17: ='Revenues, COGS & SG&A'!E23+'Revenues, COGS & SG&A'!#REF! -> #REF! | H17: =SUM(H18:H22) -> 0 | I17: =SUM(I18:I22) -> 0 | J17: =SUM(J18:J22) -> 0 | K17: =SUM(K18:K22) -> 0 | L17: =SUM(L18:L22) -> 0 | M17: =SUM(M18:M22) -> 0 | N17: =SUM(N18:N22) -> 0 | O17: =SUM(O18:O22) -> 0 | ... AD17: =SUM(AD18:AD22) -> 0
A18: =+A17+1 -> 12 | C18: Vendas Canceladas | H18: ='Revenues, COGS & SG&A'!G23 -> 0 | I18: ='Revenues, COGS & SG&A'!H23 -> 0 | J18: ='Revenues, COGS & SG&A'!I23 -> 0 | K18: ='Revenues, COGS & SG&A'!J23 -> 0 | L18: ='Revenues, COGS & SG&A'!K23 -> 0 | M18: ='Revenues, COGS & SG&A'!L23 -> 0 | N18: ='Revenues, COGS & SG&A'!M23 -> 0 | O18: ='Revenues, COGS & SG&A'!N23 -> 0 | ... AD18: ='Revenues, COGS & SG&A'!AC23 -> 0
A19: =+A18+1 -> 13 | C19: Impostos Diretos | H19: ='Revenues, COGS & SG&A'!G27 -> 0 | I19: ='Revenues, COGS & SG&A'!H27 -> 0 | J19: ='Revenues, COGS & SG&A'!I27 -> 0 | K19: ='Revenues, COGS & SG&A'!J27 -> 0 | L19: ='Revenues, COGS & SG&A'!K27 -> 0 | M19: ='Revenues, COGS & SG&A'!L27 -> 0 | N19: ='Revenues, COGS & SG&A'!M27 -> 0 | O19: ='Revenues, COGS & SG&A'!N27 -> 0 | ... AD19: ='Revenues, COGS & SG&A'!AC27 -> 0
A20: =+A19+1 -> 14 | C20: Item 3
C21: Item 4
C22: Item 5
A23: =+A20+1 -> 15
A24: =+A23+1 -> 16 | B24: = | C24: NET REVENUES | E24: =E10-E17 -> 0 | F24: =F10-F17 -> #REF! | G24: =G10-G17 -> #REF! | H24: =H10-H17 -> 2434971 | I24: =I10-I17 -> 2853511 | J24: =J10-J17 -> 3068721.7 | K24: =K10-K17 -> 3352129.3 | L24: =L10-L17 -> 3604529.7 | ... AD24: =AD10-AD17 -> 12878274
A25: =+A24+1 -> 17
A26: =+A25+1 -> 18 | B26: (-) | C26: COGS | E26: ='Revenues, COGS & SG&A'!D38 -> 0 | F26: ='Revenues, COGS & SG&A'!E38 -> 0 | G26: ='Revenues, COGS & SG&A'!F38 -> 0 | H26: =SUM(H27:H31) -> 1897818 | I26: =SUM(I27:I31) -> 2250776 | J26: =SUM(J27:J31) -> 2425322.3 | K26: =SUM(K27:K31) -> 2652824.4 | L26: =SUM(L27:L31) -> 2825774.9 | M26: =SUM(M27:M31) -> 3061587.4 | N26: =SUM(N27:N31) -> 3356477.9 | O26: =SUM(O27:O31) -> 3628553.9 | ... AD26: =SUM(AD27:AD31) -> 10196585
A27: =+A26+1 -> 19 | C27: Item 1 | H27: ='Revenues, COGS & SG&A'!G38 -> 1897818 | I27: ='Revenues, COGS & SG&A'!H38 -> 2250776 | J27: ='Revenues, COGS & SG&A'!I38 -> 2425322.3 | K27: ='Revenues, COGS & SG&A'!J38 -> 2652824.4 | L27: ='Revenues, COGS & SG&A'!K38 -> 2825774.9 | M27: ='Revenues, COGS & SG&A'!L38 -> 3061587.4 | N27: ='Revenues, COGS & SG&A'!M38 -> 3356477.9 | O27: ='Revenues, COGS & SG&A'!N38 -> 3628553.9 | ... AD27: ='Revenues, COGS & SG&A'!AC38 -> 10196585
A28: =+A27+1 -> 20 | C28: Item 2
A29: =+A28+1 -> 21 | C29: Item 3
A30: =+A29+1 -> 22 | C30: Item 4
A31: =+A30+1 -> 23 | C31: Item 5
A32: =+A31+1 -> 24
A33: =+A32+1 -> 25 | B33: = | C33: GROSS PROFIT | E33: =E24-E26 -> 0 | F33: =F24-F26 -> #REF! | G33: =G24-G26 -> #REF! | H33: =H24-H26 -> 537153 | I33: =I24-I26 -> 602735 | J33: =J24-J26 -> 643399.46 | K33: =K24-K26 -> 699304.88 | L33: =L24-L26 -> 778754.79 | ... AD33: =AD24-AD26 -> 2681689.3
A34: =+A33+1 -> 26
A35: =+A34+1 -> 27 | B35: (-) | C35: SG&A | E35: ='Revenues, COGS & SG&A'!D48 -> 0 | F35: ='Revenues, COGS & SG&A'!E48 -> 0 | G35: ='Revenues, COGS & SG&A'!F48 -> 0 | H35: =SUM(H36:H40) -> 492128 | I35: =SUM(I36:I40) -> 535439 | J35: =SUM(J36:J40) -> 575821.61 | K35: ='Revenues, COGS & SG&A'!J48 -> 629000.81 | L35: ='Revenues, COGS & SG&A'!K48 -> 676361.78 | M35: ='Revenues, COGS & SG&A'!L48 -> 728405.54 | N35: ='Revenues, COGS & SG&A'!M48 -> 786234.48 | O35: ='Revenues, COGS & SG&A'!N48 -> 848318.52 | P35: ='Revenues, COGS & SG&A'!O48 -> 915912.69 | Q35: ='Revenues, COGS & SG&A'!P48 -> 988935.93 | R35: ='Revenues, COGS & SG&A'!Q48 -> 1067176.6 | ... AD35: ='Revenues, COGS & SG&A'!AC48 -> 2290070.2
A36: =+A35+1 -> 28 | C36: Item 1 | H36: ='Revenues, COGS & SG&A'!G48 -> 492128 | I36: ='Revenues, COGS & SG&A'!H48 -> 535439 | J36: ='Revenues, COGS & SG&A'!I48 -> 575821.61 | K36: ='Revenues, COGS & SG&A'!J48 -> 629000.81 | L36: ='Revenues, COGS & SG&A'!K48 -> 676361.78 | M36: ='Revenues, COGS & SG&A'!L48 -> 728405.54 | N36: ='Revenues, COGS & SG&A'!M48 -> 786234.48 | O36: ='Revenues, COGS & SG&A'!N48 -> 848318.52 | ... AD36: ='Revenues, COGS & SG&A'!AC48 -> 2290070.2
A37: =+A36+1 -> 29 | C37: Item 2
A38: =+A37+1 -> 30 | C38: Item 3
A39: =+A38+1 -> 31 | C39: Item 4
A40: =+A39+1 -> 32 | C40: Item 5
A41: =+A40+1 -> 33
A42: =+A41+1 -> 34 | B42: = | C42: EBITDA | E42: =E33-E35 -> 0 | F42: =F33-F35+F44 -> #REF! | G42: =G33-G35+G44 -> #REF! | H42: =H33-H36+H44 -> 82461 | I42: =I33-I36+I44 -> 115501 | J42: =J33-J36+J44 -> 95584.45 | K42: =K33-K36+K44 -> 118167.81 | L42: =L33-L36+L44 -> 165665.86 | M42: =M33-M36+M44 -> 164205.03 | N42: =N33-N36+N44 -> 130003.15 | O42: =O33-O36+O44 -> 138513.19 | ... AD42: =AD33-AD36+AD44 -> 518056.22
A43: =+A42+1 -> 35
A44: =+A43+1 -> 36 | B44: (-) | C44: Depreciation and Amortization | F44: 4900 | G44: 2300 | H44: ='Revenues, COGS & SG&A'!G57 -> 37436 | I44: ='Revenues, COGS & SG&A'!H57 -> 48205 | J44: ='Fixed Assets & CAPEX'!H28 -> 28006.6 | K44: ='Fixed Assets & CAPEX'!I28 -> 47863.743 | L44: ='Fixed Assets & CAPEX'!J28 -> 63272.849 | M44: ='Fixed Assets & CAPEX'!K28 -> 72311.827 | N44: ='Fixed Assets & CAPEX'!L28 -> 82642.088 | O44: ='Fixed Assets & CAPEX'!M28 -> 94448.101 | P44: ='Fixed Assets & CAPEX'!N28 -> 107940.69 | Q44: ='Fixed Assets & CAPEX'!O28 -> 123360.79 | ... AD44: ='Fixed Assets & CAPEX'!AB28 -> 126437.15
A45: =+A44+1 -> 37
A46: =+A45+1 -> 38 | B46: (-) | C46: Goodwill Amortization | J46: ='Goodwill, Taxes & Div.'!H31 -> 0 | K46: ='Goodwill, Taxes & Div.'!I31 -> 0 | L46: ='Goodwill, Taxes & Div.'!J31 -> 0 | M46: ='Goodwill, Taxes & Div.'!K31 -> 0 | N46: ='Goodwill, Taxes & Div.'!L31 -> 0 | O46: ='Goodwill, Taxes & Div.'!M31 -> 0 | P46: ='Goodwill, Taxes & Div.'!N31 -> 0 | Q46: ='Goodwill, Taxes & Div.'!O31 -> 0 | ... AD46: ='Goodwill, Taxes & Div.'!AB31 -> 0
...

Sheet Balance Sheet
C7: BALANCE SHEET | E7: ='Revenues, COGS & SG&A'!D7 -> 39447 | F7: ='Revenues, COGS & SG&A'!E7 -> 39813 | G7: ='Revenues, COGS & SG&A'!F7 -> 40178 | H7: ='Revenues, COGS & SG&A'!G7 -> 40543 | I7: ='Revenues, COGS & SG&A'!H7 -> 40908 | J7: ='Revenues, COGS & SG&A'!I7 -> 41274 | K7: ='Revenues, COGS & SG&A'!J7 -> 41639 | L7: ='Revenues, COGS & SG&A'!K7 -> 42004 | ... AD7: ='Revenues, COGS & SG&A'!AC7 -> 48579
C8: R$ thousand
C10: ASSETS | E10: =E12+E27+E34 -> 0 | F10: =F12+F27+F34 -> 0 | G10: =G12+G27+G34 -> 0 | H10: =H12+H27+H34 -> 1414974 | I10: =I12+I27+I34 -> 1718166 | J10: =J12+J27+J34 -> 1778246 | K10: =K12+K27+K34 -> 1891710.1 | L10: =L12+L27+L34 -> 1879429.6 | ... AD10: =AD12+AD27+AD34 -> #DIV/0!
C12: Current Assets | E12: =SUM(E13:E20) -> 0 | F12: =SUM(F13:F20) -> 0 | G12: =SUM(G13:G20) -> 0 | H12: =SUM(H13:H20) -> 375922 | I12: =SUM(I13:I20) -> 601454 | J12: =SUM(J13:J20) -> 550540.62 | K12: =SUM(K13:K20) -> 604004.73 | L12: =SUM(L13:L20) -> 591724.23 | ... AD12: =SUM(AD13:AD20) -> #DIV/0!
C13: Cash & Short Term Inv. | H13: =5417+112353+104210-102022 -> 119958 | I13: =8864+167574+224351-172303 -> 228486 | J13: ='Cash Flow'!H59 -> 149443.51 | K13: ='Cash Flow'!I59 -> 165864.86 | L13: ='Cash Flow'!J59 -> 120594.37 | M13: ='Cash Flow'!K59 -> 70000 | N13: ='Cash Flow'!L59 -> 70000 | O13: ='Cash Flow'!M59 -> 70000 | P13: ='Cash Flow'!N59 -> 70000 | Q13: ='Cash Flow'!O59 -> 70000 | ... AD13: ='Cash Flow'!AB59 -> #DIV/0!
C14: Aplicações de liquidez imediata e valores em trânsito | J14: ='Working Capital'!I13 -> 0 | K14: ='Working Capital'!J13 -> 0 | L14: ='Working Capital'!K13 -> 0 | M14: ='Working Capital'!L13 -> 0 | N14: ='Working Capital'!M13 -> 0 | O14: ='Working Capital'!N13 -> 0 | P14: ='Working Capital'!O13 -> 0 | Q14: ='Working Capital'!P13 -> 0 | ... AD14: ='Working Capital'!AC13 -> 0
C15: Reserva Técnica | H15: 102022 | I15: 172303 | J15: ='Working Capital'!I14 -> 185298.03 | K15: ='Working Capital'!J14 -> 202410.97 | L15: ='Working Capital'!K14 -> 217651.62 | M15: ='Working Capital'!L14 -> 234399.17 | N15: ='Working Capital'!M14 -> 253008.39 | O15: ='Working Capital'!N14 -> 272986.89 | P15: ='Working Capital'!O14 -> 294738.53 | Q15: ='Working Capital'!P14 -> 318237.24 | ... AD15: ='Working Capital'!AC14 -> 777626.33
C16: Créd. operações pl. de assist. à saúde | H16: =86898 -> 86898 | I16: =106236 -> 106236 | J16: ='Working Capital'!I15 -> 114248.28 | K16: ='Working Capital'!J15 -> 124799.52 | L16: ='Working Capital'!K15 -> 134196.37 | M16: ='Working Capital'!L15 -> 144522.33 | N16: ='Working Capital'!M15 -> 155996.12 | O16: ='Working Capital'!N15 -> 168314.16 | P16: ='Working Capital'!O15 -> 181725.46 | Q16: ='Working Capital'!P15 -> 196213.94 | ... AD16: ='Working Capital'!AC15 -> 479457.18
C17: Despesas de comercialização diferidas | H17: 9839 | I17: 9480 | J17: ='Working Capital'!I16 -> 10194.978 | K17: ='Working Capital'!J16 -> 11136.521 | L17: ='Working Capital'!K16 -> 11975.052 | M17: ='Working Capital'!L16 -> 12896.492 | N17: ='Working Capital'!M16 -> 13920.359 | O17: ='Working Capital'!N16 -> 15019.563 | P17: ='Working Capital'!O16 -> 16216.324 | Q17: ='Working Capital'!P16 -> 17509.208 | ... AD17: ='Working Capital'!AC16 -> 42784.5
C18: Títulos e créditos a receber | H18: 45149 | I18: 52275 | J18: ='Working Capital'!I17 -> 56217.561 | K18: ='Working Capital'!J17 -> 61409.456 | L18: ='Working Capital'!K17 -> 66033.315 | M18: ='Working Capital'!L17 -> 71114.356 | N18: ='Working Capital'!M17 -> 76760.205 | O18: ='Working Capital'!N17 -> 82821.481 | P18: ='Working Capital'!O17 -> 89420.711 | Q18: ='Working Capital'!P17 -> 96549.982 | ... AD18: ='Working Capital'!AC17 -> 235924.02
C19: Outros valores e bens | H19: 12056 | I19: 32674 | J19: ='Working Capital'!I18 -> 35138.261 | K19: ='Working Capital'!J18 -> 38383.406 | L19: ='Working Capital'!K18 -> 41273.506 | M19: ='Working Capital'!L18 -> 44449.363 | N19: ='Working Capital'!M18 -> 47978.248 | O19: ='Working Capital'!N18 -> 51766.792 | P19: ='Working Capital'!O18 -> 55891.579 | Q19: ='Working Capital'!P18 -> 60347.663 | ... AD19: ='Working Capital'!AC18 -> 147462.1
C20: Other Non-Op. Cur. Assets | E20: =SUM(E21:E25) -> 0 | F20: =SUM(F21:F25) -> 0 | G20: =SUM(G21:G25) -> 0 | H20: =SUM(H21:H25) -> 0 | I20: =SUM(I21:I25) -> 0 | J20: =SUM(J21:J25) -> 0 | K20: =SUM(K21:K25) -> 0 | L20: =SUM(L21:L25) -> 0 | ... AD20: =SUM(AD21:AD25) -> 0
C21: Impostos
C22: Partes Relacionadas | J22: =I22 -> 0 | K22: =J22 -> 0 | L22: =K22 -> 0 | M22: =L22 -> 0 | N22: =M22 -> 0 | O22: =N22 -> 0 | P22: =O22 -> 0 | Q22: =P22 -> 0 | ... AD22: =AC22 -> 0
C23: Outros | J23: =I23 -> 0 | K23: =J23 -> 0 | L23: =K23 -> 0 | M23: =L23 -> 0 | N23: =M23 -> 0 | O23: =N23 -> 0 | P23: =O23 -> 0 | Q23: =P23 -> 0 | ... AD23: =AC23 -> 0
C24: item 4
C25: item 5
C27: Long-Term Assets | E27: =SUM(E28:E32) -> 0 | F27: =SUM(F28:F32) -> 0 | G27: =SUM(G28:G32) -> 0 | H27: =SUM(H28:H32) -> 741463 | I27: =SUM(I28:I32) -> 708901 | J27: =SUM(J28:J32) -> 708901 | K27: =SUM(K28:K32) -> 708901 | L27: =SUM(L28:L32) -> 708901 | ... AD27: =SUM(AD28:AD32) -> 708901
C28: Ativo Fiscal Diferido | H28: 6460 | I28: 8368 | J28: =I28 -> 8368 | K28: =J28 -> 8368 | L28: =K28 -> 8368 | M28: =L28 -> 8368 | N28: =M28 -> 8368 | O28: =N28 -> 8368 | P28: =O28 -> 8368 | Q28: =P28 -> 8368 | ... AD28: =AC28 -> 8368
C29: Valores e bens | H29: 45783 | I29: 65262 | J29: =I29 -> 65262 | K29: =J29 -> 65262 | L29: =K29 -> 65262 | M29: =L29 -> 65262 | N29: =M29 -> 65262 | O29: =N29 -> 65262 | P29: =O29 -> 65262 | Q29: =P29 -> 65262 | ... AD29: =AC29 -> 65262
C30: Conta-corrente com cooperados | H30: 689220 | I30: 635271 | J30: =I30 -> 635271 | K30: =J30 -> 635271 | L30: =K30 -> 635271 | M30: =L30 -> 635271 | N30: =M30 -> 635271 | O30: =N30 -> 635271 | P30: =O30 -> 635271 | Q30: =P30 -> 635271 | ... AD30: =AC30 -> 635271
C31: Bens destinados a venda | J31: =I31 -> 0 | K31: =J31 -> 0 | L31: =K31 -> 0 | M31: =L31 -> 0 | N31: =M31 -> 0 | O31: =N31 -> 0 | P31: =O31 -> 0 | Q31: =P31 -> 0 | ... AD31: =AC31 -> 0
C32: Impostos Diferidos | J32: =I32 -> 0 | K32: =J32 -> 0 | L32: =K32 -> 0 | M32: =L32 -> 0 | N32: =M32 -> 0 | O32: =N32 -> 0 | P32: =O32 -> 0 | Q32: =P32 -> 0 | ... AD32: =AC32 -> 0
C34: Permanent | E34: =SUM(E35:E40) -> 0 | F34: =SUM(F35:F40) -> 0 | G34: =SUM(G35:G40) -> 0 | H34: =SUM(H35:H41) -> 297589 | I34: =SUM(I35:I41) -> 407811 | J34: =SUM(J35:J41) -> 518804.4 | K34: =SUM(K35:K41) -> 578804.4 | L34: =SUM(L35:L41) -> 578804.4 | M34: =SUM(M35:M41) -> 578804.4 | N34: =SUM(N35:N41) -> 578804.4 | O34: =SUM(O35:O41) -> 578804.4 | ... AD34: =SUM(AD35:AD41) -> 578804.4
C35: Ágio | J35: =-'Cash Flow'!H38-'Goodwill, Taxes & Div.'!H29 -> 0 | K35: =J35 -> 0 | L35: =K35 -> 0 | M35: =L35 -> 0 | N35: =M35 -> 0 | O35: =N35 -> 0 | P35: =O35 -> 0 | Q35: =P35 -> 0 | R35: =Q35 -> 0 | ... AD35: =AC35 -> 0
C36: Diferido | J36: =I36 -> 0 | K36: =J36 -> 0 | L36: =K36 -> 0 | M36: =L36 -> 0 | N36: =M36 -> 0 | O36: =N36 -> 0 | P36: =O36 -> 0 | Q36: =P36 -> 0 | ... AD36: =AC36 -> 0
C37: PP&E | H37: 197195 | I37: 280066 | J37: ='Fixed Assets & CAPEX'!H10-J38 -> 419066 | K37: ='Fixed Assets & CAPEX'!I10-K38 -> 526929.74 | L37: ='Fixed Assets & CAPEX'!J10-L38 -> 590202.59 | M37: ='Fixed Assets & CAPEX'!K10-M38 -> 662514.42 | N37: ='Fixed Assets & CAPEX'!L10-N38 -> 745156.51 | O37: ='Fixed Assets & CAPEX'!M10-O38 -> 839604.61 | P37: ='Fixed Assets & CAPEX'!N10-P38 -> 947545.3 | Q37: ='Fixed Assets & CAPEX'!O10-Q38 -> 1070906.1 | ... AD37: ='Fixed Assets & CAPEX'!AB10-AD38 -> 2718339
C38: Intangíveis | J38: 0 | K38: =J38 -> 0 | L38: =K38 -> 0 | M38: =L38 -> 0 | N38: =M38 -> 0 | O38: =N38 -> 0 | P38: =O38 -> 0 | Q38: =P38 -> 0 | R38: =Q38 -> 0 | ... AD38: =AC38 -> 0
C39: Amortizacao | I39: 0 | J39: ='Fixed Assets & CAPEX'!H24 -> -28006.6 | K39: ='Fixed Assets & CAPEX'!I24 -> -75870.343 | L39: ='Fixed Assets & CAPEX'!J24 -> -139143.19 | M39: ='Fixed Assets & CAPEX'!K24 -> -211455.02 | N39: ='Fixed Assets & CAPEX'!L24 -> -294097.11 | O39: ='Fixed Assets & CAPEX'!M24 -> -388545.21 | P39: ='Fixed Assets & CAPEX'!N24 -> -496485.9 | Q39: ='Fixed Assets & CAPEX'!O24 -> -619846.68 | ... AD39: ='Fixed Assets & CAPEX'!AB24 -> -2267279.6
C40: Intangible Amortization | H40: 12791 | I40: 31238 | J40: =I40 -> 31238 | K40: =J40 -> 31238 | L40: =K40 -> 31238 | M40: =L40 -> 31238 | N40: =M40 -> 31238 | O40: =N40 -> 31238 | P40: =O40 -> 31238 | Q40: =P40 -> 31238 | ... AD40: =AC40 -> 31238
C41: Investimentos | H41: 87603 | I41: 96507 | J41: =I41 -> 96507 | K41: =J41 -> 96507 | L41: =K41 -> 96507 | M41: =L41 -> 96507 | N41: =M41 -> 96507 | O41: =N41 -> 96507 | P41: =O41 -> 96507 | Q41: =P41 -> 96507 | ... AD41: =AC41 -> 96507
C44: LIABILITIES & EQUITY | E44: =E46+E63+E77 -> 0 | F44: =F46+F63+F77 -> 0 | G44: =G46+G63+G77 -> 0 | H44: =H46+H63+H77+H73 -> 1414974 | I44: =I46+I63+I77+I73+I75 -> 1718166 | J44: =J46+J63+J77+J73+J75 -> 1778246 | K44: =K46+K63+K77+K73+K75 -> 1891710.1 | L44: =L46+L63+L77+L73+L75 -> 1879429.6 | M44: =M46+M63+M77+M73+M75 -> 1865087.1 | N44: =N46+N63+N77+N73+N75 -> 1905368.7 | O44: =O46+O63+O77+O73+O75 -> 1948614.3 | P44: =P46+P63+P77+P73+P75 -> 1995698 | ... AD44: =AD46+AD63+AD77+AD73+AD75 -> #DIV/0!
C46: Current Liabilities | E46: =SUM(E47:E61) -> 0 | F46: =SUM(F47:F61) -> 0 | G46: =SUM(G47:G61) -> 0 | H46: =SUM(H47:H56) -> 405908 | I46: =SUM(I47:I56) -> 506495 | J46: =SUM(J47:J56) -> 523744.12 | K46: =SUM(K47:K56) -> 591551.33 | L46: =SUM(L47:L56) -> 672637.27 | M46: =SUM(M47:M56) -> 728781.51 | N46: =SUM(N47:N56) -> 867606.23 | O46: =SUM(O47:O56) -> 1011976.5 | ... AD46: =SUM(AD47:AD56) -> #DIV/0!
C47: Débitos de operações de assit. à saúde | H47: 4653 | I47: 4911 | J47: ='Working Capital'!I21 -> 5281.3858 | K47: ='Working Capital'!J21 -> 5769.1408 | L47: ='Working Capital'!K21 -> 6203.5315 | M47: ='Working Capital'!L21 -> 6680.8723 | N47: ='Working Capital'!M21 -> 7211.2743 | O47: ='Working Capital'!N21 -> 7780.7038 | P47: ='Working Capital'!O21 -> 8400.6717 | Q47: ='Working Capital'!P21 -> 9070.4344 | ... AD47: ='Working Capital'!AC21 -> 22163.996
C48: Débitos de oper. assist. à saúde não rel. c/plano de saúde da op. | H48: 29653 | I48: 39339 | J48: ='Working Capital'!I22 -> 42305.933 | K48: ='Working Capital'!J22 -> 46213.038 | L48: ='Working Capital'!K22 -> 49692.675 | M48: ='Working Capital'!L22 -> 53516.359 | N48: ='Working Capital'!M22 -> 57765.083 | O48: ='Working Capital'!N22 -> 62326.432 | P48: ='Working Capital'!O22 -> 67292.613 | Q48: ='Working Capital'!P22 -> 72657.67 | ... AD48: ='Working Capital'!AC22 -> 177542.13
C49: Taxes | H49: =25896 -> 25896 | I49: =32706 -> 32706 | J49: =+'Working Capital'!I23 -> 35172.674 | K49: =+'Working Capital'!J23 -> 38420.998 | L49: =+'Working Capital'!K23 -> 41313.928 | M49: =+'Working Capital'!L23 -> 44492.896 | N49: =+'Working Capital'!M23 -> 48025.237 | O49: =+'Working Capital'!N23 -> 51817.491 | P49: =+'Working Capital'!O23 -> 55946.318 | Q49: =+'Working Capital'!P23 -> 60406.766 | ... V49: =+'Working Capital'!U23 -> 89604.054 | W49: =V49 -> 89604.054 | X49: =W49 -> 89604.054 | Y49: =X49 -> 89604.054 | Z49: =Y49 -> 89604.054 | AA49: =Z49 -> 89604.054 | AB49: =AA49 -> 89604.054 | AC49: =AB49 -> 89604.054 | AD49: =AC49 -> 89604.054
C50: Bank Short Term | H50: 75294 | I50: 49121 | J50: ='ST Inv. & Debt'!H14 -> 44928 | K50: ='ST Inv. & Debt'!I14 -> 84248.825 | L50: ='ST Inv. & Debt'!J14 -> 137426.11 | M50: ='ST Inv. & Debt'!K14 -> 120481.63 | N50: ='ST Inv. & Debt'!L14 -> 124575.83 | O50: ='ST Inv. & Debt'!M14 -> 126614.73 | P50: ='ST Inv. & Debt'!N14 -> 38897.913 | Q50: ='ST Inv. & Debt'!O14 -> 44454.758 | ... AD50: ='ST Inv. & Debt'!AB14 -> 0
C51: Tributos e contribuições a recolher - parcelamento | H51: 6767 | I51: 24196 | J51: ='Tributos a Recolher'!A7 -> 23402 | K51: ='Tributos a Recolher'!B7 -> 22606 | L51: ='Tributos a Recolher'!C7 -> 24436 | M51: ='Tributos a Recolher'!D7 -> 16987 | N51: ='Tributos a Recolher'!E7 -> 16987 | O51: ='Tributos a Recolher'!F7 -> 16987 | P51: ='Tributos a Recolher'!G7 -> 16987 | Q51: ='Tributos a Recolher'!H7 -> 16987 | R51: ='Tributos a Recolher'!I7 -> 16987
C52: Provisões técnicas de operações de assist. à saúde | H52: 171826 | I52: 217876 | J52: ='Working Capital'!I24 -> 234308.13 | K52: ='Working Capital'!J24 -> 255947.33 | L52: ='Working Capital'!K24 -> 275219.03 | M52: ='Working Capital'!L24 -> 296396.2 | N52: ='Working Capital'!M24 -> 319927.43 | O52: ='Working Capital'!N24 -> 345190.11 | P52: ='Working Capital'!O24 -> 372694.92 | Q52: ='Working Capital'!P24 -> 402408.87 | ... AD52: ='Working Capital'!AC24 -> 983303.34
C53: Dividends Payable | J53: ='Goodwill, Taxes & Div.'!H55 -> 0 | K53: ='Goodwill, Taxes & Div.'!I55 -> 0 | L53: ='Goodwill, Taxes & Div.'!J55 -> 0 | M53: ='Goodwill, Taxes & Div.'!K55 -> 0 | N53: ='Goodwill, Taxes & Div.'!L55 -> 0 | O53: ='Goodwill, Taxes & Div.'!M55 -> 0 | P53: ='Goodwill, Taxes & Div.'!N55 -> 0 | Q53: ='Goodwill, Taxes & Div.'!O55 -> 0 | ... AD53: ='Goodwill, Taxes & Div.'!AB55 -> #DIV/0!
...

Sheet Working Capital
A2: 1 | B2: ='Revenues, COGS & SG&A'!B2 -> Base Case | C2: Scenario
A3: 2 | B3: ='Revenues, COGS & SG&A'!B3 -> Client Case | C3: =Output!G2 -> 1
A4: 3 | B4: ='Revenues, COGS & SG&A'!B4 -> Stress Case | I4: ='Balance Sheet'!J83 -> 0 | J4: ='Balance Sheet'!K83 -> 0 | K4: ='Balance Sheet'!L83 -> 0 | L4: ='Balance Sheet'!M83 -> 0 | M4: ='Balance Sheet'!N83 -> 0 | N4: ='Balance Sheet'!O83 -> 0 | O4: ='Balance Sheet'!P83 -> 0 | P4: ='Balance Sheet'!Q83 -> 0 | Q4: ='Balance Sheet'!R83 -> 0
B7: WORKING CAPITAL | D7: ='Revenues, COGS & SG&A'!D7 -> 39447 | E7: ='Revenues, COGS & SG&A'!E7 -> 39813 | F7: ='Revenues, COGS & SG&A'!F7 -> 40178 | G7: ='Revenues, COGS & SG&A'!G7 -> 40543 | H7: ='Revenues, COGS & SG&A'!H7 -> 40908 | I7: ='Revenues, COGS & SG&A'!I7 -> 41274 | J7: ='Revenues, COGS & SG&A'!J7 -> 41639 | K7: ='Revenues, COGS & SG&A'!K7 -> 42004 | ... AC7: ='Revenues, COGS & SG&A'!AC7 -> 48579
B8: R$ thousand
B10: BALANCE SHEET ACCOUNTS
B12: Assets
B13: ='Balance Sheet'!C14 -> Aplicações de liquidez imediata e valores em trânsito | D13: ='Balance Sheet'!E14 -> 0 | E13: ='Balance Sheet'!F14 -> 0 | F13: ='Balance Sheet'!G14 -> 0 | G13: ='Balance Sheet'!H14 -> 0 | H13: ='Balance Sheet'!I14 -> 0 | I13: =I31/360*I37 -> 0 | J13: =J31/360*J37 -> 0 | K13: =K31/360*K37 -> 0 | L13: =L31/360*L37 -> 0 | M13: =M31/360*M37 -> 0 | N13: =N31/360*N37 -> 0 | O13: =O31/360*O37 -> 0 | P13: =P31/360*P37 -> 0 | ... AC13: =AC31/360*AC37 -> 0
B14: ='Balance Sheet'!C15 -> Reserva Técnica | D14: ='Balance Sheet'!E15 -> 0 | E14: ='Balance Sheet'!F15 -> 0 | F14: ='Balance Sheet'!G15 -> 0 | G14: ='Balance Sheet'!H15 -> 102022 | H14: ='Balance Sheet'!I15 -> 172303 | I14: =I38/360*I31 -> 185298.03 | J14: =J38/360*J31 -> 202410.97 | K14: =K38/360*K31 -> 217651.62 | L14: =L38/360*L31 -> 234399.17 | M14: =M38/360*M31 -> 253008.39 | N14: =N38/360*N31 -> 272986.89 | O14: =O38/360*O31 -> 294738.53 | P14: =P38/360*P31 -> 318237.24 | ... AC14: =AC38/360*AC31 -> 777626.33
